<?xml version="1.0" encoding="utf-8"?>
<!-- This URDF was automatically created by SolidWorks to URDF Exporter! Originally created by Stephen Brawner (brawner@gmail.com) 
     Commit Version: 1.6.0-4-g7f85cfe  Build Version: 1.6.7995.38578
     For more information, please see http://wiki.ros.org/sw_urdf_exporter -->
<robot
  name="hh020_ver1">
  <link
    name="base_link">
    <inertial>
      <origin
        xyz="-0.094837 0.00034593 0.080005"
        rpy="0 0 0" />
      <mass
        value="17.103" />
      <inertia
        ixx="0.13544"
        ixy="0.00059306"
        ixz="0.015664"
        iyy="0.31603"
        iyz="3.3743E-05"
        izz="0.37543" />
    </inertial>
    <visual>
      <origin
        xyz="0 0 0"
        rpy="0 0 0" />
      <geometry>
        <mesh
          filename="package://hh020_ver1/meshes/base_link.STL" />
      </geometry>
      <material
        name="">
        <color
          rgba="0.79216 0.81961 0.93333 1" />
      </material>
    </visual>
    <collision>
      <origin
        xyz="0 0 0"
        rpy="0 0 0" />
      <geometry>
        <mesh
          filename="package://hh020_ver1/meshes/base_link.STL" />
      </geometry>
    </collision>
  </link>
  <link
    name="lower_frame">
    <inertial>
      <origin
        xyz="0.072067 -0.0086463 0.18762"
        rpy="0 0 0" />
      <mass
        value="19.865" />
      <inertia
        ixx="0.17864"
        ixy="-0.018812"
        ixz="-0.061412"
        iyy="0.23303"
        iyz="-0.021951"
        izz="0.18982" />
    </inertial>
    <visual>
      <origin
        xyz="0 0 0"
        rpy="0 0 0" />
      <geometry>
        <mesh
          filename="package://hh020_ver1/meshes/lower_frame.STL" />
      </geometry>
      <material
        name="">
        <color
          rgba="0.79216 0.81961 0.93333 1" />
      </material>
    </visual>
    <collision>
      <origin
        xyz="0 0 0"
        rpy="0 0 0" />
      <geometry>
        <mesh
          filename="package://hh020_ver1/meshes/lower_frame.STL" />
      </geometry>
    </collision>
  </link>
  <joint
    name="lower"
    type="revolute">
    <origin
      xyz="0 0 0.162"
      rpy="0 0 0" />
    <parent
      link="base_link" />
    <child
      link="lower_frame" />
    <axis
      xyz="0 0 1" />
    <limit
      lower="-3.229"
      upper="3.229"
      effort="150"
      velocity="3.316" />
  </joint>
  <link
    name="upper_frame">
    <inertial>
      <origin
        xyz="-0.00010751 0.0068369 0.36285"
        rpy="0 0 0" />
      <mass
        value="11.176" />
      <inertia
        ixx="0.62235"
        ixy="5.5619E-06"
        ixz="0.00028138"
        iyy="0.64621"
        iyz="0.010765"
        izz="0.038783" />
    </inertial>
    <visual>
      <origin
        xyz="0 0 0"
        rpy="0 0 0" />
      <geometry>
        <mesh
          filename="package://hh020_ver1/meshes/upper_frame.STL" />
      </geometry>
      <material
        name="">
        <color
          rgba="0.79216 0.81961 0.93333 1" />
      </material>
    </visual>
    <collision>
      <origin
        xyz="0 0 0"
        rpy="0 0 0" />
      <geometry>
        <mesh
          filename="package://hh020_ver1/meshes/upper_frame.STL" />
      </geometry>
    </collision>
  </link>
  <joint
    name="upper"
    type="revolute">
    <origin
      xyz="0.16 0.1419 0.2846"
      rpy="0 0 0" />
    <parent
      link="lower_frame" />
    <child
      link="upper_frame" />
    <axis
      xyz="0 1 0" />
    <limit
      lower="-1.222"
      upper="3.403"
      effort="150"
      velocity="3.142" />
  </joint>
  <link
    name="arm_frame">
    <inertial>
      <origin
        xyz="0.042152 -0.13965 0.080961"
        rpy="0 0 0" />
      <mass
        value="12.299" />
      <inertia
        ixx="0.077578"
        ixy="0.0039974"
        ixz="-0.014934"
        iyy="0.095659"
        iyz="0.010098"
        izz="0.073131" />
    </inertial>
    <visual>
      <origin
        xyz="0 0 0"
        rpy="0 0 0" />
      <geometry>
        <mesh
          filename="package://hh020_ver1/meshes/arm_frame.STL" />
      </geometry>
      <material
        name="">
        <color
          rgba="0.79216 0.81961 0.93333 1" />
      </material>
    </visual>
    <collision>
      <origin
        xyz="0 0 0"
        rpy="0 0 0" />
      <geometry>
        <mesh
          filename="package://hh020_ver1/meshes/arm_frame.STL" />
      </geometry>
    </collision>
  </link>
  <joint
    name="arm"
    type="revolute">
    <origin
      xyz="0 -0.0104 0.77"
      rpy="0 0 0" />
    <parent
      link="upper_frame" />
    <child
      link="arm_frame" />
    <axis
      xyz="0 1 0" />
    <limit
      lower="-1.396"
      upper="3.141"
      effort="150"
      velocity="3.316" />
  </joint>
  <link
    name="wrist_frame">
    <inertial>
      <origin
        xyz="0.33419 -0.0048996 9.1409E-05"
        rpy="0 0 0" />
      <mass
        value="6.5587" />
      <inertia
        ixx="0.017572"
        ixy="0.0048652"
        ixz="-5.6686E-05"
        iyy="0.18161"
        iyz="-9.4766E-06"
        izz="0.18844" />
    </inertial>
    <visual>
      <origin
        xyz="0 0 0"
        rpy="0 0 0" />
      <geometry>
        <mesh
          filename="package://hh020_ver1/meshes/wrist_frame.STL" />
      </geometry>
      <material
        name="">
        <color
          rgba="0.79216 0.81961 0.93333 1" />
      </material>
    </visual>
    <collision>
      <origin
        xyz="0 0 0"
        rpy="0 0 0" />
      <geometry>
        <mesh
          filename="package://hh020_ver1/meshes/wrist_frame.STL" />
      </geometry>
    </collision>
  </link>
  <joint
    name="wrist"
    type="revolute">
    <origin
      xyz="0.2135 -0.1315 0.14"
      rpy="0 0 0" />
    <parent
      link="arm_frame" />
    <child
      link="wrist_frame" />
    <axis
      xyz="1 0 0" />
    <limit
      lower="-3.403"
      upper="3.403"
      effort="39.2"
      velocity="6.632" />
  </joint>
  <link
    name="end_connector">
    <inertial>
      <origin
        xyz="0.00088677 -0.061435 0.00015943"
        rpy="0 0 0" />
      <mass
        value="2.2391" />
      <inertia
        ixx="0.0040127"
        ixy="-2.7735E-06"
        ixz="-6.8315E-06"
        iyy="0.0049003"
        iyz="-7.8348E-06"
        izz="0.0052929" />
    </inertial>
    <visual>
      <origin
        xyz="0 0 0"
        rpy="0 0 0" />
      <geometry>
        <mesh
          filename="package://hh020_ver1/meshes/end_connector.STL" />
      </geometry>
      <material
        name="">
        <color
          rgba="0.79216 0.81961 0.93333 1" />
      </material>
    </visual>
    <collision>
      <origin
        xyz="0 0 0"
        rpy="0 0 0" />
      <geometry>
        <mesh
          filename="package://hh020_ver1/meshes/end_connector.STL" />
      </geometry>
    </collision>
  </link>
  <joint
    name="end_connector"
    type="revolute">
    <origin
      xyz="0.5865 0.0615 0"
      rpy="0 0 0" />
    <parent
      link="wrist_frame" />
    <child
      link="end_connector" />
    <axis
      xyz="0 -1 0" />
    <limit
      lower="-2.356"
      upper="2.356"
      effort="39.2"
      velocity="6.632" />
  </joint>
  <link
    name="end_frame">
    <inertial>
      <origin
        xyz="0.003229 -2.5625E-14 -7.2253E-06"
        rpy="0 0 0" />
      <mass
        value="0.009731" />
      <inertia
        ixx="3.6926E-06"
        ixy="8.6418E-19"
        ixz="2.0953E-10"
        iyy="1.9671E-06"
        iyz="3.8014E-18"
        izz="1.8102E-06" />
    </inertial>
    <visual>
      <origin
        xyz="0 0 0"
        rpy="0 0 0" />
      <geometry>
        <mesh
          filename="package://hh020_ver1/meshes/end_frame.STL" />
      </geometry>
      <material
        name="">
        <color
          rgba="0.79216 0.81961 0.93333 1" />
      </material>
    </visual>
    <collision>
      <origin
        xyz="0 0 0"
        rpy="0 0 0" />
      <geometry>
        <mesh
          filename="package://hh020_ver1/meshes/end_frame.STL" />
      </geometry>
    </collision>
  </link>
  <joint
    name="end"
    type="revolute">
    <origin
      xyz="0.105 -0.0615 0"
      rpy="0 0 0" />
    <parent
      link="end_connector" />
    <child
      link="end_frame" />
    <axis
      xyz="1 0 0" />
    <limit
      lower="-6.283"
      upper="6.283"
      effort="19.6"
      velocity="10.472" />
  </joint>
</robot>